<?xml version="1.0" ?>
<!-- =================================================================================== -->
<!-- |    This document was autogenerated by xacro from ./dummy_arm_full_dof.xacro     | -->
<!-- |    EDITING THIS FILE BY HAND IS NOT RECOMMENDED                                 | -->
<!-- =================================================================================== -->
<robot name="dummy_arm">
  <!-- Create the base link -->
  <link name="arm1_base"/>
  <link name="arm1_linkStart_1"/>
  <link name="arm1_linkEnd_1">
    <visual>
      <geometry>
        <mesh filename="meshes/single_segment.dae" scale="0.0006 0.0006 0.00030000000000000003"/>
      </geometry>
      <origin xyz="0 0 0.015"/>
    </visual>
    <collision>
      <geometry>
        <cylinder length="0.03" radius="0.01"/>
      </geometry>
      <origin xyz="0 0 0.015"/>
    </collision>
    <inertial>
      <mass value="0.09090909090909091"/>
      <inertia ixx="9.090909090909091e-06" ixy="0.0" ixz="0.0" iyy="9.090909090909091e-06" iyz="0.0" izz="4.5454545454545455e-06"/>
    </inertial>
  </link>
  <joint name="arm1_joint0_1" type="revolute">
    <parent link="arm1_base"/>
    <child link="arm1_linkStart_1"/>
    <axis xyz="1 0 0"/>
    <origin rpy="3.141 0 -0.7854" xyz=" 0.0 0.0 0"/>
    <limit effort="10.0" lower="-1.57" upper="1.57" velocity="1.0"/>
  </joint>
  <joint name="arm1_joint1_1" type="revolute">
    <parent link="arm1_linkStart_1"/>
    <child link="arm1_linkEnd_1"/>
    <axis xyz="0 1 0"/>
    <origin rpy="0 0 0" xyz="0 0 0"/>
    <limit effort="10.0" lower="-1.57" upper="1.57" velocity="1.0"/>
  </joint>
  <!-- Create the next link -->
  <link name="arm1_linkEnd_2">
    <visual>
      <geometry>
        <mesh filename="meshes/single_segment.dae" scale="0.0006 0.0006 0.00030000000000000003"/>
      </geometry>
      <origin xyz="0 0 0.015"/>
    </visual>
    <collision>
      <geometry>
        <cylinder length="0.03" radius="0.01"/>
      </geometry>
      <origin xyz="0 0 0.015"/>
    </collision>
    <inertial>
      <mass value="0.09090909090909091"/>
      <inertia ixx="9.090909090909091e-06" ixy="0.0" ixz="0.0" iyy="9.090909090909091e-06" iyz="0.0" izz="4.5454545454545455e-06"/>
    </inertial>
  </link>
  <!-- Create helper Links -->
  <link name="arm1_linkStart_2"/>
  <link name="arm1_linkMid_2"/>
  <!-- Create the prismatic joint -->
  <joint name="arm1_joint0_2" type="prismatic">
    <parent link="arm1_linkEnd_1"/>
    <child link="arm1_linkStart_2"/>
    <axis xyz="0 0 1"/>
    <origin rpy="0 0 0" xyz="0 0 0.03"/>
    <limit effort="10.0" lower="-0.015" upper="0" velocity="1.0"/>
  </joint>
  <!-- Create the revolute first revolute joint -->
  <joint name="arm1_joint1_2" type="revolute">
    <parent link="arm1_linkStart_2"/>
    <child link="arm1_linkMid_2"/>
    <axis xyz="0 1 0"/>
    <origin rpy="0 0 0" xyz="0 0 0"/>
    <limit effort="10.0" lower="-1.57" upper="1.57" velocity="1.0"/>
  </joint>
  <!-- Create the revolute joint -->
  <joint name="arm1_joint2_2" type="revolute">
    <parent link="arm1_linkMid_2"/>
    <child link="arm1_linkEnd_2"/>
    <axis xyz="1 0 0"/>
    <origin rpy="0 0 0" xyz="0 0 0"/>
    <limit effort="10.0" lower="-1.57" upper="1.57" velocity="1.0"/>
  </joint>
  <!-- Create the next link -->
  <link name="arm1_linkEnd_3">
    <visual>
      <geometry>
        <mesh filename="meshes/single_segment.dae" scale="0.0006 0.0006 0.00030000000000000003"/>
      </geometry>
      <origin xyz="0 0 0.015"/>
    </visual>
    <collision>
      <geometry>
        <cylinder length="0.03" radius="0.01"/>
      </geometry>
      <origin xyz="0 0 0.015"/>
    </collision>
    <inertial>
      <mass value="0.09090909090909091"/>
      <inertia ixx="9.090909090909091e-06" ixy="0.0" ixz="0.0" iyy="9.090909090909091e-06" iyz="0.0" izz="4.5454545454545455e-06"/>
    </inertial>
  </link>
  <!-- Create helper Links -->
  <link name="arm1_linkStart_3"/>
  <link name="arm1_linkMid_3"/>
  <!-- Create the prismatic joint -->
  <joint name="arm1_joint0_3" type="prismatic">
    <parent link="arm1_linkEnd_2"/>
    <child link="arm1_linkStart_3"/>
    <axis xyz="0 0 1"/>
    <origin rpy="0 0 0" xyz="0 0 0.03"/>
    <limit effort="10.0" lower="-0.015" upper="0" velocity="1.0"/>
  </joint>
  <!-- Create the revolute first revolute joint -->
  <joint name="arm1_joint1_3" type="revolute">
    <parent link="arm1_linkStart_3"/>
    <child link="arm1_linkMid_3"/>
    <axis xyz="0 1 0"/>
    <origin rpy="0 0 0" xyz="0 0 0"/>
    <limit effort="10.0" lower="-1.57" upper="1.57" velocity="1.0"/>
  </joint>
  <!-- Create the revolute joint -->
  <joint name="arm1_joint2_3" type="revolute">
    <parent link="arm1_linkMid_3"/>
    <child link="arm1_linkEnd_3"/>
    <axis xyz="1 0 0"/>
    <origin rpy="0 0 0" xyz="0 0 0"/>
    <limit effort="10.0" lower="-1.57" upper="1.57" velocity="1.0"/>
  </joint>
  <!-- Create the next link -->
  <link name="arm1_linkEnd_4">
    <visual>
      <geometry>
        <mesh filename="meshes/single_segment.dae" scale="0.0006 0.0006 0.00030000000000000003"/>
      </geometry>
      <origin xyz="0 0 0.015"/>
    </visual>
    <collision>
      <geometry>
        <cylinder length="0.03" radius="0.01"/>
      </geometry>
      <origin xyz="0 0 0.015"/>
    </collision>
    <inertial>
      <mass value="0.09090909090909091"/>
      <inertia ixx="9.090909090909091e-06" ixy="0.0" ixz="0.0" iyy="9.090909090909091e-06" iyz="0.0" izz="4.5454545454545455e-06"/>
    </inertial>
  </link>
  <!-- Create helper Links -->
  <link name="arm1_linkStart_4"/>
  <link name="arm1_linkMid_4"/>
  <!-- Create the prismatic joint -->
  <joint name="arm1_joint0_4" type="prismatic">
    <parent link="arm1_linkEnd_3"/>
    <child link="arm1_linkStart_4"/>
    <axis xyz="0 0 1"/>
    <origin rpy="0 0 0" xyz="0 0 0.03"/>
    <limit effort="10.0" lower="-0.015" upper="0" velocity="1.0"/>
  </joint>
  <!-- Create the revolute first revolute joint -->
  <joint name="arm1_joint1_4" type="revolute">
    <parent link="arm1_linkStart_4"/>
    <child link="arm1_linkMid_4"/>
    <axis xyz="0 1 0"/>
    <origin rpy="0 0 0" xyz="0 0 0"/>
    <limit effort="10.0" lower="-1.57" upper="1.57" velocity="1.0"/>
  </joint>
  <!-- Create the revolute joint -->
  <joint name="arm1_joint2_4" type="revolute">
    <parent link="arm1_linkMid_4"/>
    <child link="arm1_linkEnd_4"/>
    <axis xyz="1 0 0"/>
    <origin rpy="0 0 0" xyz="0 0 0"/>
    <limit effort="10.0" lower="-1.57" upper="1.57" velocity="1.0"/>
  </joint>
  <!-- Create the next link -->
  <link name="arm1_linkEnd_5">
    <visual>
      <geometry>
        <mesh filename="meshes/single_segment.dae" scale="0.0006 0.0006 0.00030000000000000003"/>
      </geometry>
      <origin xyz="0 0 0.015"/>
    </visual>
    <collision>
      <geometry>
        <cylinder length="0.03" radius="0.01"/>
      </geometry>
      <origin xyz="0 0 0.015"/>
    </collision>
    <inertial>
      <mass value="0.09090909090909091"/>
      <inertia ixx="9.090909090909091e-06" ixy="0.0" ixz="0.0" iyy="9.090909090909091e-06" iyz="0.0" izz="4.5454545454545455e-06"/>
    </inertial>
  </link>
  <!-- Create helper Links -->
  <link name="arm1_linkStart_5"/>
  <link name="arm1_linkMid_5"/>
  <!-- Create the prismatic joint -->
  <joint name="arm1_joint0_5" type="prismatic">
    <parent link="arm1_linkEnd_4"/>
    <child link="arm1_linkStart_5"/>
    <axis xyz="0 0 1"/>
    <origin rpy="0 0 0" xyz="0 0 0.03"/>
    <limit effort="10.0" lower="-0.015" upper="0" velocity="1.0"/>
  </joint>
  <!-- Create the revolute first revolute joint -->
  <joint name="arm1_joint1_5" type="revolute">
    <parent link="arm1_linkStart_5"/>
    <child link="arm1_linkMid_5"/>
    <axis xyz="0 1 0"/>
    <origin rpy="0 0 0" xyz="0 0 0"/>
    <limit effort="10.0" lower="-1.57" upper="1.57" velocity="1.0"/>
  </joint>
  <!-- Create the revolute joint -->
  <joint name="arm1_joint2_5" type="revolute">
    <parent link="arm1_linkMid_5"/>
    <child link="arm1_linkEnd_5"/>
    <axis xyz="1 0 0"/>
    <origin rpy="0 0 0" xyz="0 0 0"/>
    <limit effort="10.0" lower="-1.57" upper="1.57" velocity="1.0"/>
  </joint>
  <!-- Create the next link -->
  <link name="arm1_linkEnd_6">
    <visual>
      <geometry>
        <mesh filename="meshes/single_segment.dae" scale="0.0006 0.0006 0.00030000000000000003"/>
      </geometry>
      <origin xyz="0 0 0.015"/>
    </visual>
    <collision>
      <geometry>
        <cylinder length="0.03" radius="0.01"/>
      </geometry>
      <origin xyz="0 0 0.015"/>
    </collision>
    <inertial>
      <mass value="0.09090909090909091"/>
      <inertia ixx="9.090909090909091e-06" ixy="0.0" ixz="0.0" iyy="9.090909090909091e-06" iyz="0.0" izz="4.5454545454545455e-06"/>
    </inertial>
  </link>
  <!-- Create helper Links -->
  <link name="arm1_linkStart_6"/>
  <link name="arm1_linkMid_6"/>
  <!-- Create the prismatic joint -->
  <joint name="arm1_joint0_6" type="prismatic">
    <parent link="arm1_linkEnd_5"/>
    <child link="arm1_linkStart_6"/>
    <axis xyz="0 0 1"/>
    <origin rpy="0 0 0" xyz="0 0 0.03"/>
    <limit effort="10.0" lower="-0.015" upper="0" velocity="1.0"/>
  </joint>
  <!-- Create the revolute first revolute joint -->
  <joint name="arm1_joint1_6" type="revolute">
    <parent link="arm1_linkStart_6"/>
    <child link="arm1_linkMid_6"/>
    <axis xyz="0 1 0"/>
    <origin rpy="0 0 0" xyz="0 0 0"/>
    <limit effort="10.0" lower="-1.57" upper="1.57" velocity="1.0"/>
  </joint>
  <!-- Create the revolute joint -->
  <joint name="arm1_joint2_6" type="revolute">
    <parent link="arm1_linkMid_6"/>
    <child link="arm1_linkEnd_6"/>
    <axis xyz="1 0 0"/>
    <origin rpy="0 0 0" xyz="0 0 0"/>
    <limit effort="10.0" lower="-1.57" upper="1.57" velocity="1.0"/>
  </joint>
  <!-- Create the next link -->
  <link name="arm1_linkEnd_7">
    <visual>
      <geometry>
        <mesh filename="meshes/single_segment.dae" scale="0.0006 0.0006 0.00030000000000000003"/>
      </geometry>
      <origin xyz="0 0 0.015"/>
    </visual>
    <collision>
      <geometry>
        <cylinder length="0.03" radius="0.01"/>
      </geometry>
      <origin xyz="0 0 0.015"/>
    </collision>
    <inertial>
      <mass value="0.09090909090909091"/>
      <inertia ixx="9.090909090909091e-06" ixy="0.0" ixz="0.0" iyy="9.090909090909091e-06" iyz="0.0" izz="4.5454545454545455e-06"/>
    </inertial>
  </link>
  <!-- Create helper Links -->
  <link name="arm1_linkStart_7"/>
  <link name="arm1_linkMid_7"/>
  <!-- Create the prismatic joint -->
  <joint name="arm1_joint0_7" type="prismatic">
    <parent link="arm1_linkEnd_6"/>
    <child link="arm1_linkStart_7"/>
    <axis xyz="0 0 1"/>
    <origin rpy="0 0 0" xyz="0 0 0.03"/>
    <limit effort="10.0" lower="-0.015" upper="0" velocity="1.0"/>
  </joint>
  <!-- Create the revolute first revolute joint -->
  <joint name="arm1_joint1_7" type="revolute">
    <parent link="arm1_linkStart_7"/>
    <child link="arm1_linkMid_7"/>
    <axis xyz="0 1 0"/>
    <origin rpy="0 0 0" xyz="0 0 0"/>
    <limit effort="10.0" lower="-1.57" upper="1.57" velocity="1.0"/>
  </joint>
  <!-- Create the revolute joint -->
  <joint name="arm1_joint2_7" type="revolute">
    <parent link="arm1_linkMid_7"/>
    <child link="arm1_linkEnd_7"/>
    <axis xyz="1 0 0"/>
    <origin rpy="0 0 0" xyz="0 0 0"/>
    <limit effort="10.0" lower="-1.57" upper="1.57" velocity="1.0"/>
  </joint>
  <!-- Create the next link -->
  <link name="arm1_linkEnd_8">
    <visual>
      <geometry>
        <mesh filename="meshes/single_segment.dae" scale="0.0006 0.0006 0.00030000000000000003"/>
      </geometry>
      <origin xyz="0 0 0.015"/>
    </visual>
    <collision>
      <geometry>
        <cylinder length="0.03" radius="0.01"/>
      </geometry>
      <origin xyz="0 0 0.015"/>
    </collision>
    <inertial>
      <mass value="0.09090909090909091"/>
      <inertia ixx="9.090909090909091e-06" ixy="0.0" ixz="0.0" iyy="9.090909090909091e-06" iyz="0.0" izz="4.5454545454545455e-06"/>
    </inertial>
  </link>
  <!-- Create helper Links -->
  <link name="arm1_linkStart_8"/>
  <link name="arm1_linkMid_8"/>
  <!-- Create the prismatic joint -->
  <joint name="arm1_joint0_8" type="prismatic">
    <parent link="arm1_linkEnd_7"/>
    <child link="arm1_linkStart_8"/>
    <axis xyz="0 0 1"/>
    <origin rpy="0 0 0" xyz="0 0 0.03"/>
    <limit effort="10.0" lower="-0.015" upper="0" velocity="1.0"/>
  </joint>
  <!-- Create the revolute first revolute joint -->
  <joint name="arm1_joint1_8" type="revolute">
    <parent link="arm1_linkStart_8"/>
    <child link="arm1_linkMid_8"/>
    <axis xyz="0 1 0"/>
    <origin rpy="0 0 0" xyz="0 0 0"/>
    <limit effort="10.0" lower="-1.57" upper="1.57" velocity="1.0"/>
  </joint>
  <!-- Create the revolute joint -->
  <joint name="arm1_joint2_8" type="revolute">
    <parent link="arm1_linkMid_8"/>
    <child link="arm1_linkEnd_8"/>
    <axis xyz="1 0 0"/>
    <origin rpy="0 0 0" xyz="0 0 0"/>
    <limit effort="10.0" lower="-1.57" upper="1.57" velocity="1.0"/>
  </joint>
  <!-- Create the next link -->
  <link name="arm1_linkEnd_9">
    <visual>
      <geometry>
        <mesh filename="meshes/single_segment.dae" scale="0.0006 0.0006 0.00030000000000000003"/>
      </geometry>
      <origin xyz="0 0 0.015"/>
    </visual>
    <collision>
      <geometry>
        <cylinder length="0.03" radius="0.01"/>
      </geometry>
      <origin xyz="0 0 0.015"/>
    </collision>
    <inertial>
      <mass value="0.09090909090909091"/>
      <inertia ixx="9.090909090909091e-06" ixy="0.0" ixz="0.0" iyy="9.090909090909091e-06" iyz="0.0" izz="4.5454545454545455e-06"/>
    </inertial>
  </link>
  <!-- Create helper Links -->
  <link name="arm1_linkStart_9"/>
  <link name="arm1_linkMid_9"/>
  <!-- Create the prismatic joint -->
  <joint name="arm1_joint0_9" type="prismatic">
    <parent link="arm1_linkEnd_8"/>
    <child link="arm1_linkStart_9"/>
    <axis xyz="0 0 1"/>
    <origin rpy="0 0 0" xyz="0 0 0.03"/>
    <limit effort="10.0" lower="-0.015" upper="0" velocity="1.0"/>
  </joint>
  <!-- Create the revolute first revolute joint -->
  <joint name="arm1_joint1_9" type="revolute">
    <parent link="arm1_linkStart_9"/>
    <child link="arm1_linkMid_9"/>
    <axis xyz="0 1 0"/>
    <origin rpy="0 0 0" xyz="0 0 0"/>
    <limit effort="10.0" lower="-1.57" upper="1.57" velocity="1.0"/>
  </joint>
  <!-- Create the revolute joint -->
  <joint name="arm1_joint2_9" type="revolute">
    <parent link="arm1_linkMid_9"/>
    <child link="arm1_linkEnd_9"/>
    <axis xyz="1 0 0"/>
    <origin rpy="0 0 0" xyz="0 0 0"/>
    <limit effort="10.0" lower="-1.57" upper="1.57" velocity="1.0"/>
  </joint>
  <!-- Create the next link -->
  <link name="arm1_linkEnd_10">
    <visual>
      <geometry>
        <mesh filename="meshes/single_segment.dae" scale="0.0006 0.0006 0.00030000000000000003"/>
      </geometry>
      <origin xyz="0 0 0.015"/>
    </visual>
    <collision>
      <geometry>
        <cylinder length="0.03" radius="0.01"/>
      </geometry>
      <origin xyz="0 0 0.015"/>
    </collision>
    <inertial>
      <mass value="0.09090909090909091"/>
      <inertia ixx="9.090909090909091e-06" ixy="0.0" ixz="0.0" iyy="9.090909090909091e-06" iyz="0.0" izz="4.5454545454545455e-06"/>
    </inertial>
  </link>
  <!-- Create helper Links -->
  <link name="arm1_linkStart_10"/>
  <link name="arm1_linkMid_10"/>
  <!-- Create the prismatic joint -->
  <joint name="arm1_joint0_10" type="prismatic">
    <parent link="arm1_linkEnd_9"/>
    <child link="arm1_linkStart_10"/>
    <axis xyz="0 0 1"/>
    <origin rpy="0 0 0" xyz="0 0 0.03"/>
    <limit effort="10.0" lower="-0.015" upper="0" velocity="1.0"/>
  </joint>
  <!-- Create the revolute first revolute joint -->
  <joint name="arm1_joint1_10" type="revolute">
    <parent link="arm1_linkStart_10"/>
    <child link="arm1_linkMid_10"/>
    <axis xyz="0 1 0"/>
    <origin rpy="0 0 0" xyz="0 0 0"/>
    <limit effort="10.0" lower="-1.57" upper="1.57" velocity="1.0"/>
  </joint>
  <!-- Create the revolute joint -->
  <joint name="arm1_joint2_10" type="revolute">
    <parent link="arm1_linkMid_10"/>
    <child link="arm1_linkEnd_10"/>
    <axis xyz="1 0 0"/>
    <origin rpy="0 0 0" xyz="0 0 0"/>
    <limit effort="10.0" lower="-1.57" upper="1.57" velocity="1.0"/>
  </joint>
  <link name="arm1_sphere">
    <visual>
      <geometry>
        <sphere radius="0.01"/>
      </geometry>
      <origin xyz="0 0 0.01"/>
    </visual>
    <collision>
      <geometry>
        <sphere radius="0.01"/>
      </geometry>
      <origin xyz="0 0 0.01"/>
    </collision>
    <inertial>
      <mass value="0.09090909090909091"/>
      <inertia ixx="3.6363636363636366e-06" ixy="0.0" ixz="0.0" iyy="3.6363636363636366e-06" iyz="0.0" izz="3.6363636363636366e-06"/>
    </inertial>
  </link>
  <joint name="arm1_fixed_joint_sphere" type="fixed">
    <parent link="arm1_linkEnd_10"/>
    <child link="arm1_sphere"/>
    <origin rpy="0 0 0" xyz="0 0 0.019999999999999997"/>
  </joint>
</robot>
