<?xml version="1.0" ?>
<!-- =================================================================================== -->
<!-- |    This document was autogenerated by xacro from assets/drone_w_arms.xacro      | -->
<!-- |    EDITING THIS FILE BY HAND IS NOT RECOMMENDED                                 | -->
<!-- =================================================================================== -->
<robot name="drone_w_arms">
  <link name="drone_base">
    <visual>
      <origin rpy="1.5707963267948966 0 0" xyz="0 0 0"/>
      <geometry>
        <mesh filename="./meshes/Holybro-X500-V2-no-landinggear.dae" scale="0.001 0.001 0.001"/>
      </geometry>
    </visual>
    <collision>
      <origin rpy="0 0 0" xyz="0 0 -0.010000000000000002"/>
      <geometry>
        <box size="0.45 0.45 0.1"/>
      </geometry>
    </collision>
    <inertial>
      <origin rpy="0 0 0" xyz="0 0 0.225"/>
      <mass value="2.0"/>
      <inertia ixx="0.035416666666666666" ixy="0.0" ixz="0.0" iyy="0.035416666666666666" iyz="0.0" izz="0.0675"/>
    </inertial>
  </link>
  <link name="drone_prop1">
    <visual>
      <origin rpy="0 0 0" xyz="0 0 0.02"/>
      <geometry>
        <mesh filename="./meshes/1345_prop_ccw.dae" scale="0.75 0.75 0.75"/>
      </geometry>
    </visual>
    <collision>
      <origin rpy="0 0 0" xyz="0 0 0"/>
      <geometry>
        <cylinder length="0.01" radius="0.125"/>
      </geometry>
    </collision>
    <inertial>
      <origin rpy="0 0 0" xyz="0 0 0"/>
      <mass value="0"/>
      <inertia ixx="0.0" ixy="0.0" ixz="0.0" iyy="0.0" iyz="0.0" izz="0.0"/>
    </inertial>
  </link>
  <link name="drone_prop2">
    <visual>
      <origin rpy="0 0 0" xyz="0 0 0.02"/>
      <geometry>
        <mesh filename="./meshes/1345_prop_cw.dae" scale="0.75 0.75 0.75"/>
      </geometry>
    </visual>
    <collision>
      <origin rpy="0 0 0" xyz="0 0 0"/>
      <geometry>
        <cylinder length="0.01" radius="0.125"/>
      </geometry>
    </collision>
    <inertial>
      <origin rpy="0 0 0" xyz="0 0 0"/>
      <mass value="0"/>
      <inertia ixx="0.0" ixy="0.0" ixz="0.0" iyy="0.0" iyz="0.0" izz="0.0"/>
    </inertial>
  </link>
  <link name="drone_prop3">
    <visual>
      <origin rpy="0 0 0" xyz="0 0 0.02"/>
      <geometry>
        <mesh filename="./meshes/1345_prop_ccw.dae" scale="0.75 0.75 0.75"/>
      </geometry>
    </visual>
    <collision>
      <origin rpy="0 0 0" xyz="0 0 0"/>
      <geometry>
        <cylinder length="0.01" radius="0.125"/>
      </geometry>
    </collision>
    <inertial>
      <origin rpy="0 0 0" xyz="0 0 0"/>
      <mass value="0"/>
      <inertia ixx="0.0" ixy="0.0" ixz="0.0" iyy="0.0" iyz="0.0" izz="0.0"/>
    </inertial>
  </link>
  <link name="drone_prop4">
    <visual>
      <origin rpy="0 0 0" xyz="0 0 0.02"/>
      <geometry>
        <mesh filename="./meshes/1345_prop_cw.dae" scale="0.75 0.75 0.75"/>
      </geometry>
    </visual>
    <collision>
      <origin rpy="0 0 0" xyz="0 0 0"/>
      <geometry>
        <cylinder length="0.01" radius="0.125"/>
      </geometry>
    </collision>
    <inertial>
      <origin rpy="0 0 0" xyz="0 0 0"/>
      <mass value="0"/>
      <inertia ixx="0.0" ixy="0.0" ixz="0.0" iyy="0.0" iyz="0.0" izz="0.0"/>
    </inertial>
  </link>
  <joint name="drone_prop1joint" type="fixed">
    <parent link="drone_base"/>
    <child link="drone_prop1"/>
    <origin rpy="0 0 0" xyz="0.175 0.175 0.04"/>
    <!--<limit effort="3000" velocity="10000.0"/>
            <axis xyz="0 0 1" />-->
  </joint>
  <joint name="drone_prop2joint" type="fixed">
    <parent link="drone_base"/>
    <child link="drone_prop2"/>
    <origin rpy="0 0 0" xyz="-0.175 0.175 0.04"/>
    <!--<limit effort="3000" velocity="10000.0"/>
            <axis xyz="0 0 1" />-->
  </joint>
  <joint name="drone_prop3joint" type="fixed">
    <parent link="drone_base"/>
    <child link="drone_prop3"/>
    <origin rpy="0 0 0" xyz="-0.175 -0.175 0.04"/>
    <!--<limit effort="3000" velocity="10000.0"/>
            <axis xyz="0 0 1" />-->
  </joint>
  <joint name="drone_prop4joint" type="fixed">
    <parent link="drone_base"/>
    <child link="drone_prop4"/>
    <origin rpy="0 0 0" xyz="0.175 -0.175 0.04"/>
    <!--<limit effort="3000" velocity="10000.0"/>
            <axis xyz="0 0 1" />-->
  </joint>
  <!-- Define dummy links for motion generation -->
  <link name="world"/>
  <link name="p1"/>
  <link name="p2"/>
  <link name="p3"/>
  <joint name="x_pos" type="prismatic">
    <parent link="world"/>
    <child link="p1"/>
    <axis xyz="1 0 0"/>
    <dynamics damping="0" friction="0.0"/>
    <limit effort="10000" lower="-1000" upper="1000" velocity="100.0"/>
  </joint>
  <joint name="y_pos" type="prismatic">
    <parent link="p1"/>
    <child link="p2"/>
    <axis xyz="0 1 0"/>
    <dynamics damping="0" friction="0.0"/>
    <limit effort="10000" lower="-1000" upper="1000" velocity="100.0"/>
  </joint>
  <joint name="z_pos" type="prismatic">
    <parent link="p2"/>
    <child link="p3"/>
    <axis xyz="0 0 1"/>
    <dynamics damping="0" friction="0.0"/>
    <limit effort="10000" lower="-1000" upper="1000" velocity="100.0"/>
  </joint>
  <joint name="base_joint" type="continuous">
    <parent link="p3"/>
    <child link="drone_base"/>
    <axis xyz="0 0 1"/>
    <dynamics damping="0" friction="0.0"/>
    <limit effort="10000" lower="-1000" upper="1000" velocity="100.0"/>
  </joint>
  <!-- Create the base link -->
  <link name="arm1_base"/>
  <link name="arm1_link_1">
    <visual>
      <geometry>
        <mesh filename="meshes/single_segment.dae" scale="0.0006 0.0006 0.00030000000000000003"/>
      </geometry>
      <origin xyz="0 0 0.015"/>
    </visual>
    <collision>
      <geometry>
        <cylinder length="0.03" radius="0.01"/>
      </geometry>
      <origin xyz="0 0 0.015"/>
    </collision>
    <inertial>
      <mass value="0.09090909090909091"/>
      <inertia ixx="9.090909090909091e-06" ixy="0.0" ixz="0.0" iyy="9.090909090909091e-06" iyz="0.0" izz="4.5454545454545455e-06"/>
    </inertial>
  </link>
  <joint name="arm1_joint_1" type="revolute">
    <parent link="arm1_base"/>
    <child link="arm1_link_1"/>
    <axis xyz="1 0 0"/>
    <origin rpy="3.141 0 -0.7854" xyz=" 0.175  0.175 0"/>
    <limit effort="10.0" lower="-1.57" upper="1.57" velocity="1.0"/>
  </joint>
  <!-- Create the next link -->
  <link name="arm1_link_2">
    <visual>
      <geometry>
        <mesh filename="meshes/single_segment.dae" scale="0.0006 0.0006 0.00030000000000000003"/>
      </geometry>
      <origin xyz="0 0 0.015"/>
    </visual>
    <collision>
      <geometry>
        <cylinder length="0.03" radius="0.01"/>
      </geometry>
      <origin xyz="0 0 0.015"/>
    </collision>
    <inertial>
      <mass value="0.09090909090909091"/>
      <inertia ixx="9.090909090909091e-06" ixy="0.0" ixz="0.0" iyy="9.090909090909091e-06" iyz="0.0" izz="4.5454545454545455e-06"/>
    </inertial>
  </link>
  <!-- Create the revolute joint -->
  <joint name="arm1_joint_2" type="revolute">
    <parent link="arm1_link_1"/>
    <child link="arm1_link_2"/>
    <axis xyz="1 0 0"/>
    <origin rpy="0 0 0" xyz="0 0 0.03"/>
    <limit effort="10.0" lower="-1.57" upper="1.57" velocity="1.0"/>
  </joint>
  <!-- Create the next link -->
  <link name="arm1_link_3">
    <visual>
      <geometry>
        <mesh filename="meshes/single_segment.dae" scale="0.0006 0.0006 0.00030000000000000003"/>
      </geometry>
      <origin xyz="0 0 0.015"/>
    </visual>
    <collision>
      <geometry>
        <cylinder length="0.03" radius="0.01"/>
      </geometry>
      <origin xyz="0 0 0.015"/>
    </collision>
    <inertial>
      <mass value="0.09090909090909091"/>
      <inertia ixx="9.090909090909091e-06" ixy="0.0" ixz="0.0" iyy="9.090909090909091e-06" iyz="0.0" izz="4.5454545454545455e-06"/>
    </inertial>
  </link>
  <!-- Create the revolute joint -->
  <joint name="arm1_joint_3" type="revolute">
    <parent link="arm1_link_2"/>
    <child link="arm1_link_3"/>
    <axis xyz="1 0 0"/>
    <origin rpy="0 0 0" xyz="0 0 0.03"/>
    <limit effort="10.0" lower="-1.57" upper="1.57" velocity="1.0"/>
  </joint>
  <!-- Create the next link -->
  <link name="arm1_link_4">
    <visual>
      <geometry>
        <mesh filename="meshes/single_segment.dae" scale="0.0006 0.0006 0.00030000000000000003"/>
      </geometry>
      <origin xyz="0 0 0.015"/>
    </visual>
    <collision>
      <geometry>
        <cylinder length="0.03" radius="0.01"/>
      </geometry>
      <origin xyz="0 0 0.015"/>
    </collision>
    <inertial>
      <mass value="0.09090909090909091"/>
      <inertia ixx="9.090909090909091e-06" ixy="0.0" ixz="0.0" iyy="9.090909090909091e-06" iyz="0.0" izz="4.5454545454545455e-06"/>
    </inertial>
  </link>
  <!-- Create the revolute joint -->
  <joint name="arm1_joint_4" type="revolute">
    <parent link="arm1_link_3"/>
    <child link="arm1_link_4"/>
    <axis xyz="1 0 0"/>
    <origin rpy="0 0 0" xyz="0 0 0.03"/>
    <limit effort="10.0" lower="-1.57" upper="1.57" velocity="1.0"/>
  </joint>
  <!-- Create the next link -->
  <link name="arm1_link_5">
    <visual>
      <geometry>
        <mesh filename="meshes/single_segment.dae" scale="0.0006 0.0006 0.00030000000000000003"/>
      </geometry>
      <origin xyz="0 0 0.015"/>
    </visual>
    <collision>
      <geometry>
        <cylinder length="0.03" radius="0.01"/>
      </geometry>
      <origin xyz="0 0 0.015"/>
    </collision>
    <inertial>
      <mass value="0.09090909090909091"/>
      <inertia ixx="9.090909090909091e-06" ixy="0.0" ixz="0.0" iyy="9.090909090909091e-06" iyz="0.0" izz="4.5454545454545455e-06"/>
    </inertial>
  </link>
  <!-- Create the revolute joint -->
  <joint name="arm1_joint_5" type="revolute">
    <parent link="arm1_link_4"/>
    <child link="arm1_link_5"/>
    <axis xyz="1 0 0"/>
    <origin rpy="0 0 0" xyz="0 0 0.03"/>
    <limit effort="10.0" lower="-1.57" upper="1.57" velocity="1.0"/>
  </joint>
  <!-- Create the next link -->
  <link name="arm1_link_6">
    <visual>
      <geometry>
        <mesh filename="meshes/single_segment.dae" scale="0.0006 0.0006 0.00030000000000000003"/>
      </geometry>
      <origin xyz="0 0 0.015"/>
    </visual>
    <collision>
      <geometry>
        <cylinder length="0.03" radius="0.01"/>
      </geometry>
      <origin xyz="0 0 0.015"/>
    </collision>
    <inertial>
      <mass value="0.09090909090909091"/>
      <inertia ixx="9.090909090909091e-06" ixy="0.0" ixz="0.0" iyy="9.090909090909091e-06" iyz="0.0" izz="4.5454545454545455e-06"/>
    </inertial>
  </link>
  <!-- Create the revolute joint -->
  <joint name="arm1_joint_6" type="revolute">
    <parent link="arm1_link_5"/>
    <child link="arm1_link_6"/>
    <axis xyz="1 0 0"/>
    <origin rpy="0 0 0" xyz="0 0 0.03"/>
    <limit effort="10.0" lower="-1.57" upper="1.57" velocity="1.0"/>
  </joint>
  <!-- Create the next link -->
  <link name="arm1_link_7">
    <visual>
      <geometry>
        <mesh filename="meshes/single_segment.dae" scale="0.0006 0.0006 0.00030000000000000003"/>
      </geometry>
      <origin xyz="0 0 0.015"/>
    </visual>
    <collision>
      <geometry>
        <cylinder length="0.03" radius="0.01"/>
      </geometry>
      <origin xyz="0 0 0.015"/>
    </collision>
    <inertial>
      <mass value="0.09090909090909091"/>
      <inertia ixx="9.090909090909091e-06" ixy="0.0" ixz="0.0" iyy="9.090909090909091e-06" iyz="0.0" izz="4.5454545454545455e-06"/>
    </inertial>
  </link>
  <!-- Create the revolute joint -->
  <joint name="arm1_joint_7" type="revolute">
    <parent link="arm1_link_6"/>
    <child link="arm1_link_7"/>
    <axis xyz="1 0 0"/>
    <origin rpy="0 0 0" xyz="0 0 0.03"/>
    <limit effort="10.0" lower="-1.57" upper="1.57" velocity="1.0"/>
  </joint>
  <!-- Create the next link -->
  <link name="arm1_link_8">
    <visual>
      <geometry>
        <mesh filename="meshes/single_segment.dae" scale="0.0006 0.0006 0.00030000000000000003"/>
      </geometry>
      <origin xyz="0 0 0.015"/>
    </visual>
    <collision>
      <geometry>
        <cylinder length="0.03" radius="0.01"/>
      </geometry>
      <origin xyz="0 0 0.015"/>
    </collision>
    <inertial>
      <mass value="0.09090909090909091"/>
      <inertia ixx="9.090909090909091e-06" ixy="0.0" ixz="0.0" iyy="9.090909090909091e-06" iyz="0.0" izz="4.5454545454545455e-06"/>
    </inertial>
  </link>
  <!-- Create the revolute joint -->
  <joint name="arm1_joint_8" type="revolute">
    <parent link="arm1_link_7"/>
    <child link="arm1_link_8"/>
    <axis xyz="1 0 0"/>
    <origin rpy="0 0 0" xyz="0 0 0.03"/>
    <limit effort="10.0" lower="-1.57" upper="1.57" velocity="1.0"/>
  </joint>
  <!-- Create the next link -->
  <link name="arm1_link_9">
    <visual>
      <geometry>
        <mesh filename="meshes/single_segment.dae" scale="0.0006 0.0006 0.00030000000000000003"/>
      </geometry>
      <origin xyz="0 0 0.015"/>
    </visual>
    <collision>
      <geometry>
        <cylinder length="0.03" radius="0.01"/>
      </geometry>
      <origin xyz="0 0 0.015"/>
    </collision>
    <inertial>
      <mass value="0.09090909090909091"/>
      <inertia ixx="9.090909090909091e-06" ixy="0.0" ixz="0.0" iyy="9.090909090909091e-06" iyz="0.0" izz="4.5454545454545455e-06"/>
    </inertial>
  </link>
  <!-- Create the revolute joint -->
  <joint name="arm1_joint_9" type="revolute">
    <parent link="arm1_link_8"/>
    <child link="arm1_link_9"/>
    <axis xyz="1 0 0"/>
    <origin rpy="0 0 0" xyz="0 0 0.03"/>
    <limit effort="10.0" lower="-1.57" upper="1.57" velocity="1.0"/>
  </joint>
  <!-- Create the next link -->
  <link name="arm1_link_10">
    <visual>
      <geometry>
        <mesh filename="meshes/single_segment.dae" scale="0.0006 0.0006 0.00030000000000000003"/>
      </geometry>
      <origin xyz="0 0 0.015"/>
    </visual>
    <collision>
      <geometry>
        <cylinder length="0.03" radius="0.01"/>
      </geometry>
      <origin xyz="0 0 0.015"/>
    </collision>
    <inertial>
      <mass value="0.09090909090909091"/>
      <inertia ixx="9.090909090909091e-06" ixy="0.0" ixz="0.0" iyy="9.090909090909091e-06" iyz="0.0" izz="4.5454545454545455e-06"/>
    </inertial>
  </link>
  <!-- Create the revolute joint -->
  <joint name="arm1_joint_10" type="revolute">
    <parent link="arm1_link_9"/>
    <child link="arm1_link_10"/>
    <axis xyz="1 0 0"/>
    <origin rpy="0 0 0" xyz="0 0 0.03"/>
    <limit effort="10.0" lower="-1.57" upper="1.57" velocity="1.0"/>
  </joint>
  <link name="arm1_sphere">
    <visual>
      <geometry>
        <sphere radius="0.01"/>
      </geometry>
      <origin xyz="0 0 0.01"/>
    </visual>
    <collision>
      <geometry>
        <sphere radius="0.01"/>
      </geometry>
      <origin xyz="0 0 0.01"/>
    </collision>
    <inertial>
      <mass value="0.09090909090909091"/>
      <inertia ixx="3.6363636363636366e-06" ixy="0.0" ixz="0.0" iyy="3.6363636363636366e-06" iyz="0.0" izz="3.6363636363636366e-06"/>
    </inertial>
  </link>
  <joint name="arm1_fixed_joint_sphere" type="fixed">
    <parent link="arm1_link_10"/>
    <child link="arm1_sphere"/>
    <origin rpy="0 0 0" xyz="0 0 0.019999999999999997"/>
  </joint>
  <!-- Create the base link -->
  <link name="arm2_base"/>
  <link name="arm2_link_1">
    <visual>
      <geometry>
        <mesh filename="meshes/single_segment.dae" scale="0.0006 0.0006 0.00030000000000000003"/>
      </geometry>
      <origin xyz="0 0 0.015"/>
    </visual>
    <collision>
      <geometry>
        <cylinder length="0.03" radius="0.01"/>
      </geometry>
      <origin xyz="0 0 0.015"/>
    </collision>
    <inertial>
      <mass value="0.09090909090909091"/>
      <inertia ixx="9.090909090909091e-06" ixy="0.0" ixz="0.0" iyy="9.090909090909091e-06" iyz="0.0" izz="4.5454545454545455e-06"/>
    </inertial>
  </link>
  <joint name="arm2_joint_1" type="revolute">
    <parent link="arm2_base"/>
    <child link="arm2_link_1"/>
    <axis xyz="1 0 0"/>
    <origin rpy="3.141 0 -2.3562" xyz=" 0.175 -0.175 0"/>
    <limit effort="10.0" lower="-1.57" upper="1.57" velocity="1.0"/>
  </joint>
  <!-- Create the next link -->
  <link name="arm2_link_2">
    <visual>
      <geometry>
        <mesh filename="meshes/single_segment.dae" scale="0.0006 0.0006 0.00030000000000000003"/>
      </geometry>
      <origin xyz="0 0 0.015"/>
    </visual>
    <collision>
      <geometry>
        <cylinder length="0.03" radius="0.01"/>
      </geometry>
      <origin xyz="0 0 0.015"/>
    </collision>
    <inertial>
      <mass value="0.09090909090909091"/>
      <inertia ixx="9.090909090909091e-06" ixy="0.0" ixz="0.0" iyy="9.090909090909091e-06" iyz="0.0" izz="4.5454545454545455e-06"/>
    </inertial>
  </link>
  <!-- Create the revolute joint -->
  <joint name="arm2_joint_2" type="revolute">
    <parent link="arm2_link_1"/>
    <child link="arm2_link_2"/>
    <axis xyz="1 0 0"/>
    <origin rpy="0 0 0" xyz="0 0 0.03"/>
    <limit effort="10.0" lower="-1.57" upper="1.57" velocity="1.0"/>
  </joint>
  <!-- Create the next link -->
  <link name="arm2_link_3">
    <visual>
      <geometry>
        <mesh filename="meshes/single_segment.dae" scale="0.0006 0.0006 0.00030000000000000003"/>
      </geometry>
      <origin xyz="0 0 0.015"/>
    </visual>
    <collision>
      <geometry>
        <cylinder length="0.03" radius="0.01"/>
      </geometry>
      <origin xyz="0 0 0.015"/>
    </collision>
    <inertial>
      <mass value="0.09090909090909091"/>
      <inertia ixx="9.090909090909091e-06" ixy="0.0" ixz="0.0" iyy="9.090909090909091e-06" iyz="0.0" izz="4.5454545454545455e-06"/>
    </inertial>
  </link>
  <!-- Create the revolute joint -->
  <joint name="arm2_joint_3" type="revolute">
    <parent link="arm2_link_2"/>
    <child link="arm2_link_3"/>
    <axis xyz="1 0 0"/>
    <origin rpy="0 0 0" xyz="0 0 0.03"/>
    <limit effort="10.0" lower="-1.57" upper="1.57" velocity="1.0"/>
  </joint>
  <!-- Create the next link -->
  <link name="arm2_link_4">
    <visual>
      <geometry>
        <mesh filename="meshes/single_segment.dae" scale="0.0006 0.0006 0.00030000000000000003"/>
      </geometry>
      <origin xyz="0 0 0.015"/>
    </visual>
    <collision>
      <geometry>
        <cylinder length="0.03" radius="0.01"/>
      </geometry>
      <origin xyz="0 0 0.015"/>
    </collision>
    <inertial>
      <mass value="0.09090909090909091"/>
      <inertia ixx="9.090909090909091e-06" ixy="0.0" ixz="0.0" iyy="9.090909090909091e-06" iyz="0.0" izz="4.5454545454545455e-06"/>
    </inertial>
  </link>
  <!-- Create the revolute joint -->
  <joint name="arm2_joint_4" type="revolute">
    <parent link="arm2_link_3"/>
    <child link="arm2_link_4"/>
    <axis xyz="1 0 0"/>
    <origin rpy="0 0 0" xyz="0 0 0.03"/>
    <limit effort="10.0" lower="-1.57" upper="1.57" velocity="1.0"/>
  </joint>
  <!-- Create the next link -->
  <link name="arm2_link_5">
    <visual>
      <geometry>
        <mesh filename="meshes/single_segment.dae" scale="0.0006 0.0006 0.00030000000000000003"/>
      </geometry>
      <origin xyz="0 0 0.015"/>
    </visual>
    <collision>
      <geometry>
        <cylinder length="0.03" radius="0.01"/>
      </geometry>
      <origin xyz="0 0 0.015"/>
    </collision>
    <inertial>
      <mass value="0.09090909090909091"/>
      <inertia ixx="9.090909090909091e-06" ixy="0.0" ixz="0.0" iyy="9.090909090909091e-06" iyz="0.0" izz="4.5454545454545455e-06"/>
    </inertial>
  </link>
  <!-- Create the revolute joint -->
  <joint name="arm2_joint_5" type="revolute">
    <parent link="arm2_link_4"/>
    <child link="arm2_link_5"/>
    <axis xyz="1 0 0"/>
    <origin rpy="0 0 0" xyz="0 0 0.03"/>
    <limit effort="10.0" lower="-1.57" upper="1.57" velocity="1.0"/>
  </joint>
  <!-- Create the next link -->
  <link name="arm2_link_6">
    <visual>
      <geometry>
        <mesh filename="meshes/single_segment.dae" scale="0.0006 0.0006 0.00030000000000000003"/>
      </geometry>
      <origin xyz="0 0 0.015"/>
    </visual>
    <collision>
      <geometry>
        <cylinder length="0.03" radius="0.01"/>
      </geometry>
      <origin xyz="0 0 0.015"/>
    </collision>
    <inertial>
      <mass value="0.09090909090909091"/>
      <inertia ixx="9.090909090909091e-06" ixy="0.0" ixz="0.0" iyy="9.090909090909091e-06" iyz="0.0" izz="4.5454545454545455e-06"/>
    </inertial>
  </link>
  <!-- Create the revolute joint -->
  <joint name="arm2_joint_6" type="revolute">
    <parent link="arm2_link_5"/>
    <child link="arm2_link_6"/>
    <axis xyz="1 0 0"/>
    <origin rpy="0 0 0" xyz="0 0 0.03"/>
    <limit effort="10.0" lower="-1.57" upper="1.57" velocity="1.0"/>
  </joint>
  <!-- Create the next link -->
  <link name="arm2_link_7">
    <visual>
      <geometry>
        <mesh filename="meshes/single_segment.dae" scale="0.0006 0.0006 0.00030000000000000003"/>
      </geometry>
      <origin xyz="0 0 0.015"/>
    </visual>
    <collision>
      <geometry>
        <cylinder length="0.03" radius="0.01"/>
      </geometry>
      <origin xyz="0 0 0.015"/>
    </collision>
    <inertial>
      <mass value="0.09090909090909091"/>
      <inertia ixx="9.090909090909091e-06" ixy="0.0" ixz="0.0" iyy="9.090909090909091e-06" iyz="0.0" izz="4.5454545454545455e-06"/>
    </inertial>
  </link>
  <!-- Create the revolute joint -->
  <joint name="arm2_joint_7" type="revolute">
    <parent link="arm2_link_6"/>
    <child link="arm2_link_7"/>
    <axis xyz="1 0 0"/>
    <origin rpy="0 0 0" xyz="0 0 0.03"/>
    <limit effort="10.0" lower="-1.57" upper="1.57" velocity="1.0"/>
  </joint>
  <!-- Create the next link -->
  <link name="arm2_link_8">
    <visual>
      <geometry>
        <mesh filename="meshes/single_segment.dae" scale="0.0006 0.0006 0.00030000000000000003"/>
      </geometry>
      <origin xyz="0 0 0.015"/>
    </visual>
    <collision>
      <geometry>
        <cylinder length="0.03" radius="0.01"/>
      </geometry>
      <origin xyz="0 0 0.015"/>
    </collision>
    <inertial>
      <mass value="0.09090909090909091"/>
      <inertia ixx="9.090909090909091e-06" ixy="0.0" ixz="0.0" iyy="9.090909090909091e-06" iyz="0.0" izz="4.5454545454545455e-06"/>
    </inertial>
  </link>
  <!-- Create the revolute joint -->
  <joint name="arm2_joint_8" type="revolute">
    <parent link="arm2_link_7"/>
    <child link="arm2_link_8"/>
    <axis xyz="1 0 0"/>
    <origin rpy="0 0 0" xyz="0 0 0.03"/>
    <limit effort="10.0" lower="-1.57" upper="1.57" velocity="1.0"/>
  </joint>
  <!-- Create the next link -->
  <link name="arm2_link_9">
    <visual>
      <geometry>
        <mesh filename="meshes/single_segment.dae" scale="0.0006 0.0006 0.00030000000000000003"/>
      </geometry>
      <origin xyz="0 0 0.015"/>
    </visual>
    <collision>
      <geometry>
        <cylinder length="0.03" radius="0.01"/>
      </geometry>
      <origin xyz="0 0 0.015"/>
    </collision>
    <inertial>
      <mass value="0.09090909090909091"/>
      <inertia ixx="9.090909090909091e-06" ixy="0.0" ixz="0.0" iyy="9.090909090909091e-06" iyz="0.0" izz="4.5454545454545455e-06"/>
    </inertial>
  </link>
  <!-- Create the revolute joint -->
  <joint name="arm2_joint_9" type="revolute">
    <parent link="arm2_link_8"/>
    <child link="arm2_link_9"/>
    <axis xyz="1 0 0"/>
    <origin rpy="0 0 0" xyz="0 0 0.03"/>
    <limit effort="10.0" lower="-1.57" upper="1.57" velocity="1.0"/>
  </joint>
  <!-- Create the next link -->
  <link name="arm2_link_10">
    <visual>
      <geometry>
        <mesh filename="meshes/single_segment.dae" scale="0.0006 0.0006 0.00030000000000000003"/>
      </geometry>
      <origin xyz="0 0 0.015"/>
    </visual>
    <collision>
      <geometry>
        <cylinder length="0.03" radius="0.01"/>
      </geometry>
      <origin xyz="0 0 0.015"/>
    </collision>
    <inertial>
      <mass value="0.09090909090909091"/>
      <inertia ixx="9.090909090909091e-06" ixy="0.0" ixz="0.0" iyy="9.090909090909091e-06" iyz="0.0" izz="4.5454545454545455e-06"/>
    </inertial>
  </link>
  <!-- Create the revolute joint -->
  <joint name="arm2_joint_10" type="revolute">
    <parent link="arm2_link_9"/>
    <child link="arm2_link_10"/>
    <axis xyz="1 0 0"/>
    <origin rpy="0 0 0" xyz="0 0 0.03"/>
    <limit effort="10.0" lower="-1.57" upper="1.57" velocity="1.0"/>
  </joint>
  <link name="arm2_sphere">
    <visual>
      <geometry>
        <sphere radius="0.01"/>
      </geometry>
      <origin xyz="0 0 0.01"/>
    </visual>
    <collision>
      <geometry>
        <sphere radius="0.01"/>
      </geometry>
      <origin xyz="0 0 0.01"/>
    </collision>
    <inertial>
      <mass value="0.09090909090909091"/>
      <inertia ixx="3.6363636363636366e-06" ixy="0.0" ixz="0.0" iyy="3.6363636363636366e-06" iyz="0.0" izz="3.6363636363636366e-06"/>
    </inertial>
  </link>
  <joint name="arm2_fixed_joint_sphere" type="fixed">
    <parent link="arm2_link_10"/>
    <child link="arm2_sphere"/>
    <origin rpy="0 0 0" xyz="0 0 0.019999999999999997"/>
  </joint>
  <!-- Create the base link -->
  <link name="arm3_base"/>
  <link name="arm3_link_1">
    <visual>
      <geometry>
        <mesh filename="meshes/single_segment.dae" scale="0.0006 0.0006 0.00030000000000000003"/>
      </geometry>
      <origin xyz="0 0 0.015"/>
    </visual>
    <collision>
      <geometry>
        <cylinder length="0.03" radius="0.01"/>
      </geometry>
      <origin xyz="0 0 0.015"/>
    </collision>
    <inertial>
      <mass value="0.09090909090909091"/>
      <inertia ixx="9.090909090909091e-06" ixy="0.0" ixz="0.0" iyy="9.090909090909091e-06" iyz="0.0" izz="4.5454545454545455e-06"/>
    </inertial>
  </link>
  <joint name="arm3_joint_1" type="revolute">
    <parent link="arm3_base"/>
    <child link="arm3_link_1"/>
    <axis xyz="1 0 0"/>
    <origin rpy="3.141 0 2.3562" xyz="-0.175 -0.175 0"/>
    <limit effort="10.0" lower="-1.57" upper="1.57" velocity="1.0"/>
  </joint>
  <!-- Create the next link -->
  <link name="arm3_link_2">
    <visual>
      <geometry>
        <mesh filename="meshes/single_segment.dae" scale="0.0006 0.0006 0.00030000000000000003"/>
      </geometry>
      <origin xyz="0 0 0.015"/>
    </visual>
    <collision>
      <geometry>
        <cylinder length="0.03" radius="0.01"/>
      </geometry>
      <origin xyz="0 0 0.015"/>
    </collision>
    <inertial>
      <mass value="0.09090909090909091"/>
      <inertia ixx="9.090909090909091e-06" ixy="0.0" ixz="0.0" iyy="9.090909090909091e-06" iyz="0.0" izz="4.5454545454545455e-06"/>
    </inertial>
  </link>
  <!-- Create the revolute joint -->
  <joint name="arm3_joint_2" type="revolute">
    <parent link="arm3_link_1"/>
    <child link="arm3_link_2"/>
    <axis xyz="1 0 0"/>
    <origin rpy="0 0 0" xyz="0 0 0.03"/>
    <limit effort="10.0" lower="-1.57" upper="1.57" velocity="1.0"/>
  </joint>
  <!-- Create the next link -->
  <link name="arm3_link_3">
    <visual>
      <geometry>
        <mesh filename="meshes/single_segment.dae" scale="0.0006 0.0006 0.00030000000000000003"/>
      </geometry>
      <origin xyz="0 0 0.015"/>
    </visual>
    <collision>
      <geometry>
        <cylinder length="0.03" radius="0.01"/>
      </geometry>
      <origin xyz="0 0 0.015"/>
    </collision>
    <inertial>
      <mass value="0.09090909090909091"/>
      <inertia ixx="9.090909090909091e-06" ixy="0.0" ixz="0.0" iyy="9.090909090909091e-06" iyz="0.0" izz="4.5454545454545455e-06"/>
    </inertial>
  </link>
  <!-- Create the revolute joint -->
  <joint name="arm3_joint_3" type="revolute">
    <parent link="arm3_link_2"/>
    <child link="arm3_link_3"/>
    <axis xyz="1 0 0"/>
    <origin rpy="0 0 0" xyz="0 0 0.03"/>
    <limit effort="10.0" lower="-1.57" upper="1.57" velocity="1.0"/>
  </joint>
  <!-- Create the next link -->
  <link name="arm3_link_4">
    <visual>
      <geometry>
        <mesh filename="meshes/single_segment.dae" scale="0.0006 0.0006 0.00030000000000000003"/>
      </geometry>
      <origin xyz="0 0 0.015"/>
    </visual>
    <collision>
      <geometry>
        <cylinder length="0.03" radius="0.01"/>
      </geometry>
      <origin xyz="0 0 0.015"/>
    </collision>
    <inertial>
      <mass value="0.09090909090909091"/>
      <inertia ixx="9.090909090909091e-06" ixy="0.0" ixz="0.0" iyy="9.090909090909091e-06" iyz="0.0" izz="4.5454545454545455e-06"/>
    </inertial>
  </link>
  <!-- Create the revolute joint -->
  <joint name="arm3_joint_4" type="revolute">
    <parent link="arm3_link_3"/>
    <child link="arm3_link_4"/>
    <axis xyz="1 0 0"/>
    <origin rpy="0 0 0" xyz="0 0 0.03"/>
    <limit effort="10.0" lower="-1.57" upper="1.57" velocity="1.0"/>
  </joint>
  <!-- Create the next link -->
  <link name="arm3_link_5">
    <visual>
      <geometry>
        <mesh filename="meshes/single_segment.dae" scale="0.0006 0.0006 0.00030000000000000003"/>
      </geometry>
      <origin xyz="0 0 0.015"/>
    </visual>
    <collision>
      <geometry>
        <cylinder length="0.03" radius="0.01"/>
      </geometry>
      <origin xyz="0 0 0.015"/>
    </collision>
    <inertial>
      <mass value="0.09090909090909091"/>
      <inertia ixx="9.090909090909091e-06" ixy="0.0" ixz="0.0" iyy="9.090909090909091e-06" iyz="0.0" izz="4.5454545454545455e-06"/>
    </inertial>
  </link>
  <!-- Create the revolute joint -->
  <joint name="arm3_joint_5" type="revolute">
    <parent link="arm3_link_4"/>
    <child link="arm3_link_5"/>
    <axis xyz="1 0 0"/>
    <origin rpy="0 0 0" xyz="0 0 0.03"/>
    <limit effort="10.0" lower="-1.57" upper="1.57" velocity="1.0"/>
  </joint>
  <!-- Create the next link -->
  <link name="arm3_link_6">
    <visual>
      <geometry>
        <mesh filename="meshes/single_segment.dae" scale="0.0006 0.0006 0.00030000000000000003"/>
      </geometry>
      <origin xyz="0 0 0.015"/>
    </visual>
    <collision>
      <geometry>
        <cylinder length="0.03" radius="0.01"/>
      </geometry>
      <origin xyz="0 0 0.015"/>
    </collision>
    <inertial>
      <mass value="0.09090909090909091"/>
      <inertia ixx="9.090909090909091e-06" ixy="0.0" ixz="0.0" iyy="9.090909090909091e-06" iyz="0.0" izz="4.5454545454545455e-06"/>
    </inertial>
  </link>
  <!-- Create the revolute joint -->
  <joint name="arm3_joint_6" type="revolute">
    <parent link="arm3_link_5"/>
    <child link="arm3_link_6"/>
    <axis xyz="1 0 0"/>
    <origin rpy="0 0 0" xyz="0 0 0.03"/>
    <limit effort="10.0" lower="-1.57" upper="1.57" velocity="1.0"/>
  </joint>
  <!-- Create the next link -->
  <link name="arm3_link_7">
    <visual>
      <geometry>
        <mesh filename="meshes/single_segment.dae" scale="0.0006 0.0006 0.00030000000000000003"/>
      </geometry>
      <origin xyz="0 0 0.015"/>
    </visual>
    <collision>
      <geometry>
        <cylinder length="0.03" radius="0.01"/>
      </geometry>
      <origin xyz="0 0 0.015"/>
    </collision>
    <inertial>
      <mass value="0.09090909090909091"/>
      <inertia ixx="9.090909090909091e-06" ixy="0.0" ixz="0.0" iyy="9.090909090909091e-06" iyz="0.0" izz="4.5454545454545455e-06"/>
    </inertial>
  </link>
  <!-- Create the revolute joint -->
  <joint name="arm3_joint_7" type="revolute">
    <parent link="arm3_link_6"/>
    <child link="arm3_link_7"/>
    <axis xyz="1 0 0"/>
    <origin rpy="0 0 0" xyz="0 0 0.03"/>
    <limit effort="10.0" lower="-1.57" upper="1.57" velocity="1.0"/>
  </joint>
  <!-- Create the next link -->
  <link name="arm3_link_8">
    <visual>
      <geometry>
        <mesh filename="meshes/single_segment.dae" scale="0.0006 0.0006 0.00030000000000000003"/>
      </geometry>
      <origin xyz="0 0 0.015"/>
    </visual>
    <collision>
      <geometry>
        <cylinder length="0.03" radius="0.01"/>
      </geometry>
      <origin xyz="0 0 0.015"/>
    </collision>
    <inertial>
      <mass value="0.09090909090909091"/>
      <inertia ixx="9.090909090909091e-06" ixy="0.0" ixz="0.0" iyy="9.090909090909091e-06" iyz="0.0" izz="4.5454545454545455e-06"/>
    </inertial>
  </link>
  <!-- Create the revolute joint -->
  <joint name="arm3_joint_8" type="revolute">
    <parent link="arm3_link_7"/>
    <child link="arm3_link_8"/>
    <axis xyz="1 0 0"/>
    <origin rpy="0 0 0" xyz="0 0 0.03"/>
    <limit effort="10.0" lower="-1.57" upper="1.57" velocity="1.0"/>
  </joint>
  <!-- Create the next link -->
  <link name="arm3_link_9">
    <visual>
      <geometry>
        <mesh filename="meshes/single_segment.dae" scale="0.0006 0.0006 0.00030000000000000003"/>
      </geometry>
      <origin xyz="0 0 0.015"/>
    </visual>
    <collision>
      <geometry>
        <cylinder length="0.03" radius="0.01"/>
      </geometry>
      <origin xyz="0 0 0.015"/>
    </collision>
    <inertial>
      <mass value="0.09090909090909091"/>
      <inertia ixx="9.090909090909091e-06" ixy="0.0" ixz="0.0" iyy="9.090909090909091e-06" iyz="0.0" izz="4.5454545454545455e-06"/>
    </inertial>
  </link>
  <!-- Create the revolute joint -->
  <joint name="arm3_joint_9" type="revolute">
    <parent link="arm3_link_8"/>
    <child link="arm3_link_9"/>
    <axis xyz="1 0 0"/>
    <origin rpy="0 0 0" xyz="0 0 0.03"/>
    <limit effort="10.0" lower="-1.57" upper="1.57" velocity="1.0"/>
  </joint>
  <!-- Create the next link -->
  <link name="arm3_link_10">
    <visual>
      <geometry>
        <mesh filename="meshes/single_segment.dae" scale="0.0006 0.0006 0.00030000000000000003"/>
      </geometry>
      <origin xyz="0 0 0.015"/>
    </visual>
    <collision>
      <geometry>
        <cylinder length="0.03" radius="0.01"/>
      </geometry>
      <origin xyz="0 0 0.015"/>
    </collision>
    <inertial>
      <mass value="0.09090909090909091"/>
      <inertia ixx="9.090909090909091e-06" ixy="0.0" ixz="0.0" iyy="9.090909090909091e-06" iyz="0.0" izz="4.5454545454545455e-06"/>
    </inertial>
  </link>
  <!-- Create the revolute joint -->
  <joint name="arm3_joint_10" type="revolute">
    <parent link="arm3_link_9"/>
    <child link="arm3_link_10"/>
    <axis xyz="1 0 0"/>
    <origin rpy="0 0 0" xyz="0 0 0.03"/>
    <limit effort="10.0" lower="-1.57" upper="1.57" velocity="1.0"/>
  </joint>
  <link name="arm3_sphere">
    <visual>
      <geometry>
        <sphere radius="0.01"/>
      </geometry>
      <origin xyz="0 0 0.01"/>
    </visual>
    <collision>
      <geometry>
        <sphere radius="0.01"/>
      </geometry>
      <origin xyz="0 0 0.01"/>
    </collision>
    <inertial>
      <mass value="0.09090909090909091"/>
      <inertia ixx="3.6363636363636366e-06" ixy="0.0" ixz="0.0" iyy="3.6363636363636366e-06" iyz="0.0" izz="3.6363636363636366e-06"/>
    </inertial>
  </link>
  <joint name="arm3_fixed_joint_sphere" type="fixed">
    <parent link="arm3_link_10"/>
    <child link="arm3_sphere"/>
    <origin rpy="0 0 0" xyz="0 0 0.019999999999999997"/>
  </joint>
  <!-- Create the base link -->
  <link name="arm4_base"/>
  <link name="arm4_link_1">
    <visual>
      <geometry>
        <mesh filename="meshes/single_segment.dae" scale="0.0006 0.0006 0.00030000000000000003"/>
      </geometry>
      <origin xyz="0 0 0.015"/>
    </visual>
    <collision>
      <geometry>
        <cylinder length="0.03" radius="0.01"/>
      </geometry>
      <origin xyz="0 0 0.015"/>
    </collision>
    <inertial>
      <mass value="0.09090909090909091"/>
      <inertia ixx="9.090909090909091e-06" ixy="0.0" ixz="0.0" iyy="9.090909090909091e-06" iyz="0.0" izz="4.5454545454545455e-06"/>
    </inertial>
  </link>
  <joint name="arm4_joint_1" type="revolute">
    <parent link="arm4_base"/>
    <child link="arm4_link_1"/>
    <axis xyz="1 0 0"/>
    <origin rpy="3.141 0 0.7854" xyz="-0.175  0.175 0"/>
    <limit effort="10.0" lower="-1.57" upper="1.57" velocity="1.0"/>
  </joint>
  <!-- Create the next link -->
  <link name="arm4_link_2">
    <visual>
      <geometry>
        <mesh filename="meshes/single_segment.dae" scale="0.0006 0.0006 0.00030000000000000003"/>
      </geometry>
      <origin xyz="0 0 0.015"/>
    </visual>
    <collision>
      <geometry>
        <cylinder length="0.03" radius="0.01"/>
      </geometry>
      <origin xyz="0 0 0.015"/>
    </collision>
    <inertial>
      <mass value="0.09090909090909091"/>
      <inertia ixx="9.090909090909091e-06" ixy="0.0" ixz="0.0" iyy="9.090909090909091e-06" iyz="0.0" izz="4.5454545454545455e-06"/>
    </inertial>
  </link>
  <!-- Create the revolute joint -->
  <joint name="arm4_joint_2" type="revolute">
    <parent link="arm4_link_1"/>
    <child link="arm4_link_2"/>
    <axis xyz="1 0 0"/>
    <origin rpy="0 0 0" xyz="0 0 0.03"/>
    <limit effort="10.0" lower="-1.57" upper="1.57" velocity="1.0"/>
  </joint>
  <!-- Create the next link -->
  <link name="arm4_link_3">
    <visual>
      <geometry>
        <mesh filename="meshes/single_segment.dae" scale="0.0006 0.0006 0.00030000000000000003"/>
      </geometry>
      <origin xyz="0 0 0.015"/>
    </visual>
    <collision>
      <geometry>
        <cylinder length="0.03" radius="0.01"/>
      </geometry>
      <origin xyz="0 0 0.015"/>
    </collision>
    <inertial>
      <mass value="0.09090909090909091"/>
      <inertia ixx="9.090909090909091e-06" ixy="0.0" ixz="0.0" iyy="9.090909090909091e-06" iyz="0.0" izz="4.5454545454545455e-06"/>
    </inertial>
  </link>
  <!-- Create the revolute joint -->
  <joint name="arm4_joint_3" type="revolute">
    <parent link="arm4_link_2"/>
    <child link="arm4_link_3"/>
    <axis xyz="1 0 0"/>
    <origin rpy="0 0 0" xyz="0 0 0.03"/>
    <limit effort="10.0" lower="-1.57" upper="1.57" velocity="1.0"/>
  </joint>
  <!-- Create the next link -->
  <link name="arm4_link_4">
    <visual>
      <geometry>
        <mesh filename="meshes/single_segment.dae" scale="0.0006 0.0006 0.00030000000000000003"/>
      </geometry>
      <origin xyz="0 0 0.015"/>
    </visual>
    <collision>
      <geometry>
        <cylinder length="0.03" radius="0.01"/>
      </geometry>
      <origin xyz="0 0 0.015"/>
    </collision>
    <inertial>
      <mass value="0.09090909090909091"/>
      <inertia ixx="9.090909090909091e-06" ixy="0.0" ixz="0.0" iyy="9.090909090909091e-06" iyz="0.0" izz="4.5454545454545455e-06"/>
    </inertial>
  </link>
  <!-- Create the revolute joint -->
  <joint name="arm4_joint_4" type="revolute">
    <parent link="arm4_link_3"/>
    <child link="arm4_link_4"/>
    <axis xyz="1 0 0"/>
    <origin rpy="0 0 0" xyz="0 0 0.03"/>
    <limit effort="10.0" lower="-1.57" upper="1.57" velocity="1.0"/>
  </joint>
  <!-- Create the next link -->
  <link name="arm4_link_5">
    <visual>
      <geometry>
        <mesh filename="meshes/single_segment.dae" scale="0.0006 0.0006 0.00030000000000000003"/>
      </geometry>
      <origin xyz="0 0 0.015"/>
    </visual>
    <collision>
      <geometry>
        <cylinder length="0.03" radius="0.01"/>
      </geometry>
      <origin xyz="0 0 0.015"/>
    </collision>
    <inertial>
      <mass value="0.09090909090909091"/>
      <inertia ixx="9.090909090909091e-06" ixy="0.0" ixz="0.0" iyy="9.090909090909091e-06" iyz="0.0" izz="4.5454545454545455e-06"/>
    </inertial>
  </link>
  <!-- Create the revolute joint -->
  <joint name="arm4_joint_5" type="revolute">
    <parent link="arm4_link_4"/>
    <child link="arm4_link_5"/>
    <axis xyz="1 0 0"/>
    <origin rpy="0 0 0" xyz="0 0 0.03"/>
    <limit effort="10.0" lower="-1.57" upper="1.57" velocity="1.0"/>
  </joint>
  <!-- Create the next link -->
  <link name="arm4_link_6">
    <visual>
      <geometry>
        <mesh filename="meshes/single_segment.dae" scale="0.0006 0.0006 0.00030000000000000003"/>
      </geometry>
      <origin xyz="0 0 0.015"/>
    </visual>
    <collision>
      <geometry>
        <cylinder length="0.03" radius="0.01"/>
      </geometry>
      <origin xyz="0 0 0.015"/>
    </collision>
    <inertial>
      <mass value="0.09090909090909091"/>
      <inertia ixx="9.090909090909091e-06" ixy="0.0" ixz="0.0" iyy="9.090909090909091e-06" iyz="0.0" izz="4.5454545454545455e-06"/>
    </inertial>
  </link>
  <!-- Create the revolute joint -->
  <joint name="arm4_joint_6" type="revolute">
    <parent link="arm4_link_5"/>
    <child link="arm4_link_6"/>
    <axis xyz="1 0 0"/>
    <origin rpy="0 0 0" xyz="0 0 0.03"/>
    <limit effort="10.0" lower="-1.57" upper="1.57" velocity="1.0"/>
  </joint>
  <!-- Create the next link -->
  <link name="arm4_link_7">
    <visual>
      <geometry>
        <mesh filename="meshes/single_segment.dae" scale="0.0006 0.0006 0.00030000000000000003"/>
      </geometry>
      <origin xyz="0 0 0.015"/>
    </visual>
    <collision>
      <geometry>
        <cylinder length="0.03" radius="0.01"/>
      </geometry>
      <origin xyz="0 0 0.015"/>
    </collision>
    <inertial>
      <mass value="0.09090909090909091"/>
      <inertia ixx="9.090909090909091e-06" ixy="0.0" ixz="0.0" iyy="9.090909090909091e-06" iyz="0.0" izz="4.5454545454545455e-06"/>
    </inertial>
  </link>
  <!-- Create the revolute joint -->
  <joint name="arm4_joint_7" type="revolute">
    <parent link="arm4_link_6"/>
    <child link="arm4_link_7"/>
    <axis xyz="1 0 0"/>
    <origin rpy="0 0 0" xyz="0 0 0.03"/>
    <limit effort="10.0" lower="-1.57" upper="1.57" velocity="1.0"/>
  </joint>
  <!-- Create the next link -->
  <link name="arm4_link_8">
    <visual>
      <geometry>
        <mesh filename="meshes/single_segment.dae" scale="0.0006 0.0006 0.00030000000000000003"/>
      </geometry>
      <origin xyz="0 0 0.015"/>
    </visual>
    <collision>
      <geometry>
        <cylinder length="0.03" radius="0.01"/>
      </geometry>
      <origin xyz="0 0 0.015"/>
    </collision>
    <inertial>
      <mass value="0.09090909090909091"/>
      <inertia ixx="9.090909090909091e-06" ixy="0.0" ixz="0.0" iyy="9.090909090909091e-06" iyz="0.0" izz="4.5454545454545455e-06"/>
    </inertial>
  </link>
  <!-- Create the revolute joint -->
  <joint name="arm4_joint_8" type="revolute">
    <parent link="arm4_link_7"/>
    <child link="arm4_link_8"/>
    <axis xyz="1 0 0"/>
    <origin rpy="0 0 0" xyz="0 0 0.03"/>
    <limit effort="10.0" lower="-1.57" upper="1.57" velocity="1.0"/>
  </joint>
  <!-- Create the next link -->
  <link name="arm4_link_9">
    <visual>
      <geometry>
        <mesh filename="meshes/single_segment.dae" scale="0.0006 0.0006 0.00030000000000000003"/>
      </geometry>
      <origin xyz="0 0 0.015"/>
    </visual>
    <collision>
      <geometry>
        <cylinder length="0.03" radius="0.01"/>
      </geometry>
      <origin xyz="0 0 0.015"/>
    </collision>
    <inertial>
      <mass value="0.09090909090909091"/>
      <inertia ixx="9.090909090909091e-06" ixy="0.0" ixz="0.0" iyy="9.090909090909091e-06" iyz="0.0" izz="4.5454545454545455e-06"/>
    </inertial>
  </link>
  <!-- Create the revolute joint -->
  <joint name="arm4_joint_9" type="revolute">
    <parent link="arm4_link_8"/>
    <child link="arm4_link_9"/>
    <axis xyz="1 0 0"/>
    <origin rpy="0 0 0" xyz="0 0 0.03"/>
    <limit effort="10.0" lower="-1.57" upper="1.57" velocity="1.0"/>
  </joint>
  <!-- Create the next link -->
  <link name="arm4_link_10">
    <visual>
      <geometry>
        <mesh filename="meshes/single_segment.dae" scale="0.0006 0.0006 0.00030000000000000003"/>
      </geometry>
      <origin xyz="0 0 0.015"/>
    </visual>
    <collision>
      <geometry>
        <cylinder length="0.03" radius="0.01"/>
      </geometry>
      <origin xyz="0 0 0.015"/>
    </collision>
    <inertial>
      <mass value="0.09090909090909091"/>
      <inertia ixx="9.090909090909091e-06" ixy="0.0" ixz="0.0" iyy="9.090909090909091e-06" iyz="0.0" izz="4.5454545454545455e-06"/>
    </inertial>
  </link>
  <!-- Create the revolute joint -->
  <joint name="arm4_joint_10" type="revolute">
    <parent link="arm4_link_9"/>
    <child link="arm4_link_10"/>
    <axis xyz="1 0 0"/>
    <origin rpy="0 0 0" xyz="0 0 0.03"/>
    <limit effort="10.0" lower="-1.57" upper="1.57" velocity="1.0"/>
  </joint>
  <link name="arm4_sphere">
    <visual>
      <geometry>
        <sphere radius="0.01"/>
      </geometry>
      <origin xyz="0 0 0.01"/>
    </visual>
    <collision>
      <geometry>
        <sphere radius="0.01"/>
      </geometry>
      <origin xyz="0 0 0.01"/>
    </collision>
    <inertial>
      <mass value="0.09090909090909091"/>
      <inertia ixx="3.6363636363636366e-06" ixy="0.0" ixz="0.0" iyy="3.6363636363636366e-06" iyz="0.0" izz="3.6363636363636366e-06"/>
    </inertial>
  </link>
  <joint name="arm4_fixed_joint_sphere" type="fixed">
    <parent link="arm4_link_10"/>
    <child link="arm4_sphere"/>
    <origin rpy="0 0 0" xyz="0 0 0.019999999999999997"/>
  </joint>
  <joint name="arm1_joint" type="fixed">
    <parent link="drone_base"/>
    <child link="arm1_base"/>
  </joint>
  <joint name="arm2_joint" type="fixed">
    <parent link="drone_base"/>
    <child link="arm2_base"/>
  </joint>
  <joint name="arm3_joint" type="fixed">
    <parent link="drone_base"/>
    <child link="arm3_base"/>
  </joint>
  <joint name="arm4_joint" type="fixed">
    <parent link="drone_base"/>
    <child link="arm4_base"/>
  </joint>
</robot>
